Workbook

Sheet INPUTS
A1: INPUTS
O2: Male | P2: Bulking
A3: Starting Date | B3: 42149 | O3: Female | P3: Cutting
A4: Male of Female | B4: Male
A5: Bulking or Cutting | B5: Cutting
A6: Starting Weight (lbs) | B6: 190
A7: Height (cm) | B7: 168
A8: Starting Calories | B8: =IF(AND(B4="Male", B5="Bulking"), B6*15, "") | C8: =IF(AND(B4="Female", B5="Bulking"), B6*14, "")
B9: =IF(AND(B4="Male", B5="Cutting"), B6*12, "") -> 2280 | C9: =IF(AND(B4="Female", B5="Cutting"), B6*11, "")
A10: Input Starting Calories | B10: 2330.4
A11: Current Calories | B11: 2330.4
A12: Macronutrient Breakdown | B12: High Carb Day | C12: Low Carb Day
A13: Protein | B13: =IF(B5="Cutting",MROUND(B6*1.1,5),MROUND(B6,5)) -> 210 | C13: =IF(B5="Cutting", MROUND(B6*1.2, 5), MROUND(B6+10, 5)) -> 230
A14: Carbs | B14: =IFERROR(IF(B5="Cutting",MROUND((((B11+500)-(B13*4)-(B15*9))/4),5),MROUND((((B11+500)-(B13*4)-(B15*9))/4),5)),0) -> 355 | C14: =IFERROR(MROUND((((B11)-(C13*4)-(C15*9))/4),1),0) -> 222
A15: Fat | B15: =MROUND(((B11+500)*0.2)/9,1) -> 63 | C15: =IF(B5="Cutting", MROUND((B11*0.225)/9, 1), MROUND((B11*0.25)/9, 1)) -> 58
A16: Fibre | B16: =IF(B14>20, MROUND(B14/10,1), 20) -> 36 | C16: =IF(C14>20, MROUND(C14/10,1), 20) -> 22
A19: Notes
A20: Any cell highlighted yellow | C20: is your responsibility to track
A21: Hide hips on tracker if male
A22: Bulk between 10-15% if male, 18-23% if female

Sheet CUTTING TRACKER
A1: Date | B1: Weight | C1: Waist (cm) | D1: Neck (cm) | E1: Hips* (cm) | F1: Bodyfat | G1: LBM | H1: Average Weight | I1: Percent Difference | J1: Protocol | P1: Calories Added | Q1: New Calories | R1: Notes
A3: =INPUTS!B3 -> 42149 | C3: 90.5 | D3: 39 | F3: =IFERROR(IF(INPUTS!B4="Male", 86.01*LOG(C3-D3)-70.041*LOG(INPUTS!B$7)+30.3, 163.205*LOG(C3+E3-D3)-97.684*LOG(INPUTS!B$7)-104.912),0) -> 21.669652 | G3: =(B3)*((100-F3)/100) -> 0 | P3: =INPUTS!B10 -> 2330.4
A4: =A3+1 -> 42150
A5: =A4+1 -> 42151
A6: =A5+1 -> 42152
A7: =A6+1 -> 42153 | R7: Start of Week 2 EC
A8: =A7+1 -> 42154
A9: =A8+1 -> 42155 | I9: =AVERAGE(B3:B5) -> #DIV/0!
A10: =A9+1 -> 42156 | F10: =IFERROR(IF(INPUTS!B10="Male", 86.01*LOG(C10-D10)-70.041*LOG(INPUTS!B$7)+30.3, 163.205*LOG('CUTTING TRACKER'!C10+'CUTTING TRACKER'!E10-'CUTTING TRACKER'!D10)-97.684*LOG(INPUTS!B$7)-104.912),0) -> 0 | G10: =(B10)*((100-F10)/100) -> 0 | H10: =IFERROR((AVERAGE(B3:B10)),0) -> 0 | I10: =IFERROR(IF(B10>0, (I9-H10)/I9,0.007), 0) -> 0.007 | J10: =IF(I10<0, "Cut 200kcal", "") | K10: =IF(AND(I10<0.005, I10>=0), "Cut 100kcal", "") | L10: =IF(AND(I10<0.006, I10>=0.005), "Cut 50kcal", "") | M10: =IF(AND(I10<0.008, I10>=0.006), "Remain Constant", " ") -> Remain Constant | N10: =IF(AND(I10>=0.008,I10<0.01), "Add 50kcal", "") | O10: =IF(I10>=0.01, "Add 100kcal", "")
A11: =A10+1 -> 42157
A12: =A11+1 -> 42158
A13: =A12+1 -> 42159
A14: =A13+1 -> 42160 | R14: Week 3
A15: =A14+1 -> 42161
A16: =A15+1 -> 42162
A17: =A16+1 -> 42163 | F17: =IFERROR(IF(INPUTS!B18="Male", 86.01*LOG(C17-D17)-70.041*LOG(INPUTS!B$7)+30.3, 163.205*LOG('CUTTING TRACKER'!C17+'CUTTING TRACKER'!E17-'CUTTING TRACKER'!D17)-97.684*LOG(INPUTS!B$7)-104.912),0) -> 0 | G17: =(B17)*((100-F17)/100) -> 0 | H17: =IFERROR((AVERAGE(B11:B17)),0) -> 0 | I17: =IFERROR(IF(B17>0, (H10-H17)/H10,0.007), 0) -> 0.007 | J17: =IF(I17<0, "Cut 200kcal", "") | K17: =IF(AND(I17<0.005, I17>=0), "Cut 100kcal", "") | L17: =IF(AND(I17<0.006, I17>=0.005), "Cut 50kcal", "") | M17: =IF(AND(I17<0.008, I17>=0.006), "Remain Constant", " ") -> Remain Constant | N17: =IF(AND(I17>=0.008,I17<0.01), "Add 50kcal", "") | O17: =IF(I17>=0.01, "Add 100kcal", "") | P17: -100 | Q17: =IF(H17>0,$P$3+P17,"")
A18: =A17+1 -> 42164
A19: =A18+1 -> 42165
A20: =A19+1 -> 42166
A21: =A20+1 -> 42167 | R21: Week 4
A22: =A21+1 -> 42168
A23: =A22+1 -> 42169
A24: =A23+1 -> 42170 | F24: =IFERROR(IF(INPUTS!B25="Male", 86.01*LOG(C24-D24)-70.041*LOG(INPUTS!B$7)+30.3, 163.205*LOG('CUTTING TRACKER'!C24+'CUTTING TRACKER'!E24-'CUTTING TRACKER'!D24)-97.684*LOG(INPUTS!B$7)-104.912),0) -> 0 | G24: =(B24)*((100-F24)/100) -> 0 | H24: =IFERROR((AVERAGE(B18:B24)),0) -> 0 | I24: =IFERROR(IF(B24>0, (H17-H24)/H17,0.007), 0) -> 0.007 | J24: =IF(I24<0, "Cut 200kcal", "") | K24: =IF(AND(I24<0.005, I24>=0), "Cut 100kcal", "") | L24: =IF(AND(I24<0.006, I24>=0.005), "Cut 50kcal", "") | M24: =IF(AND(I24<0.008, I24>=0.006), "Remain Constant", "") -> Remain Constant | N24: =IF(AND(I24>=0.008,I24<0.01), "Add 50kcal", "") | O24: =IF(I24>=0.01, "Add 100kcal", "") | Q24: =IF(P24>0,Q17+P24,"")
A25: =A24+1 -> 42171
A26: =A25+1 -> 42172
A27: =A26+1 -> 42173
A28: =A27+1 -> 42174 | R28: Week 5
A29: =A28+1 -> 42175
A30: =A29+1 -> 42176
A31: =A30+1 -> 42177 | F31: =IFERROR(IF(INPUTS!B32="Male", 86.01*LOG(C31-D31)-70.041*LOG(INPUTS!B$7)+30.3, 163.205*LOG('CUTTING TRACKER'!C31+'CUTTING TRACKER'!E31-'CUTTING TRACKER'!D31)-97.684*LOG(INPUTS!B$7)-104.912),0) -> 0 | G31: =(B31)*((100-F31)/100) -> 0 | H31: =IFERROR((AVERAGE(B25:B31)),0) -> 0 | I31: =IFERROR(IF(B31>0, (H24-H31)/H24,0.007), 0) -> 0.007 | J31: =IF(I31<0, "Cut 200kcal", "") | K31: =IF(AND(I31<0.005, I31>=0), "Cut 100kcal", "") | L31: =IF(AND(I31<0.006, I31>=0.005), "Cut 50kcal", "") | M31: =IF(AND(I31<0.008, I31>=0.006), "Remain Constant", "") -> Remain Constant | N31: =IF(AND(I31>=0.008,I31<0.01), "Add 50kcal", "") | O31: =IF(I31>=0.01, "Add 100kcal", "") | Q31: =IF(P31>0,Q24+P31,"")
A32: =A31+1 -> 42178
A33: =A32+1 -> 42179
A34: =A33+1 -> 42180
A35: =A34+1 -> 42181 | R35: Week 6
A36: =A35+1 -> 42182
A37: =A36+1 -> 42183
A38: =A37+1 -> 42184 | F38: =IFERROR(IF(INPUTS!B39="Male", 86.01*LOG(C38-D38)-70.041*LOG(INPUTS!B$7)+30.3, 163.205*LOG('CUTTING TRACKER'!C38+'CUTTING TRACKER'!E38-'CUTTING TRACKER'!D38)-97.684*LOG(INPUTS!B$7)-104.912),0) -> 0 | G38: =(B38)*((100-F38)/100) -> 0 | H38: =IFERROR((AVERAGE(B32:B38)),0) -> 0 | I38: =IFERROR(IF(B38>0, (H31-H38)/H31,0.007), 0) -> 0.007 | J38: =IF(I38<0, "Cut 200kcal", "") | K38: =IF(AND(I38<0.005, I38>=0), "Cut 100kcal", "") | L38: =IF(AND(I38<0.006, I38>=0.005), "Cut 50kcal", "") | M38: =IF(AND(I38<0.008, I38>=0.006), "Remain Constant", "") -> Remain Constant | N38: =IF(AND(I38>=0.008,I38<0.01), "Add 50kcal", "") | O38: =IF(I38>=0.01, "Add 100kcal", "") | Q38: =IF(P38>0,$P$3+P38,"")
A39: =A38+1 -> 42185
A40: =A39+1 -> 42186
A41: =A40+1 -> 42187
...

Sheet BULKING TRACKER
A1: Date | B1: Weight | C1: Waist (cm) | D1: Neck (cm) | E1: Hips* (cm) | F1: Bodyfat | G1: Average Weight | H1: Percent Difference | I1: Protocol | O1: Calories Added | P1: New Calories
A3: =INPUTS!B3 -> 42149 | F3: =IFERROR(IF(INPUTS!B4="Male", 86.01*LOG(C3-D3)-70.041*LOG(INPUTS!B$7)+30.3, 163.205*LOG(C3+E3-D3)-97.684*LOG(INPUTS!B$7)-104.912),0) -> 0 | O3: =INPUTS!B10 -> 2330.4
A4: =A3+1 -> 42150
A5: =A4+1 -> 42151
A6: =A5+1 -> 42152
A7: =A6+1 -> 42153
A8: =A7+1 -> 42154
A9: =A8+1 -> 42155
A10: =A9+1 -> 42156 | F10: =IFERROR(IF(INPUTS!B10="Male", 86.01*LOG(C10-D10)-70.041*LOG(INPUTS!B$7)+30.3, 163.205*LOG('BULKING TRACKER'!C10+'BULKING TRACKER'!E10-'BULKING TRACKER'!D10)-97.684*LOG(INPUTS!B$7)-104.912),0) -> 0 | G10: =IFERROR((AVERAGE(B3:B10)),0) -> 0
A11: =A10+1 -> 42157
A12: =A11+1 -> 42158
A13: =A12+1 -> 42159
A14: =A13+1 -> 42160
A15: =A14+1 -> 42161
A16: =A15+1 -> 42162
A17: =A16+1 -> 42163 | F17: =IFERROR(IF(INPUTS!B18="Male", 86.01*LOG(C17-D17)-70.041*LOG(INPUTS!B$7)+30.3, 163.205*LOG('BULKING TRACKER'!C17+'BULKING TRACKER'!E17-'BULKING TRACKER'!D17)-97.684*LOG(INPUTS!B$7)-104.912),0) -> 0 | G17: =IFERROR((AVERAGE(B11:B17)),0) -> 0 | H17: =IFERROR(IF(B17>0, (G10-G17)/G10,0.007), 0) -> 0.007 | I17: =IF(H17<-0.005, "Add 200kcal", "") | J17: =IF(AND(H17>=-0.005, H17<-0.001), "Add 100kcal", "") | K17: =IF(AND(H17<0.001, H17>=-0.001), "Add 50kcal", "") | L17: =IF(AND(H17<=0.003, H17>=0.001), "Remain Constant", " ") | M17: =IF(AND(H17>0.003,H17<=0.005), "Cut 50kcal", "") | N17: =IF(H17>0.005, "Cut 100kcal", "") -> Cut 100kcal | P17: =IF(O17>0,$O$3+O17,"")
A18: =A17+1 -> 42164
A19: =A18+1 -> 42165
A20: =A19+1 -> 42166
A21: =A20+1 -> 42167
A22: =A21+1 -> 42168
A23: =A22+1 -> 42169
A24: =A23+1 -> 42170 | F24: =IFERROR(IF(INPUTS!B25="Male", 86.01*LOG(C24-D24)-70.041*LOG(INPUTS!B$7)+30.3, 163.205*LOG('BULKING TRACKER'!C24+'BULKING TRACKER'!E24-'BULKING TRACKER'!D24)-97.684*LOG(INPUTS!B$7)-104.912),0) -> 0 | G24: =IFERROR((AVERAGE(B18:B24)),0) -> 0 | H24: =IFERROR(IF(B24>0, (G17-G24)/G17,0.007), 0) -> 0.007 | I24: =IF(H24<0, "Cut 200kcal", "") | J24: =IF(AND(H24<0.005, H24>=0), "Cut 100kcal", "") | K24: =IF(AND(H24<0.006, H24>=0.005), "Cut 50kcal", "") | L24: =IF(AND(H24<0.008, H24>=0.006), "Remain Constant", "") -> Remain Constant | M24: =IF(AND(H24>=0.008,H24<0.01), "Add 50kcal", "") | N24: =IF(H24>=0.01, "Add 100kcal", "") | P24: =IF(O24>0,P17+O24,"")
A25: =A24+1 -> 42171
A26: =A25+1 -> 42172
A27: =A26+1 -> 42173
A28: =A27+1 -> 42174
A29: =A28+1 -> 42175
A30: =A29+1 -> 42176
A31: =A30+1 -> 42177 | F31: =IFERROR(IF(INPUTS!B32="Male", 86.01*LOG(C31-D31)-70.041*LOG(INPUTS!B$7)+30.3, 163.205*LOG('BULKING TRACKER'!C31+'BULKING TRACKER'!E31-'BULKING TRACKER'!D31)-97.684*LOG(INPUTS!B$7)-104.912),0) -> 0 | G31: =IFERROR((AVERAGE(B25:B31)),0) -> 0 | H31: =IFERROR(IF(B31>0, (G24-G31)/G24,0.007), 0) -> 0.007 | I31: =IF(H31<0, "Cut 200kcal", "") | J31: =IF(AND(H31<0.005, H31>=0), "Cut 100kcal", "") | K31: =IF(AND(H31<0.006, H31>=0.005), "Cut 50kcal", "") | L31: =IF(AND(H31<0.008, H31>=0.006), "Remain Constant", "") -> Remain Constant | M31: =IF(AND(H31>=0.008,H31<0.01), "Add 50kcal", "") | N31: =IF(H31>=0.01, "Add 100kcal", "") | P31: =IF(O31>0,P24+O31,"")
A32: =A31+1 -> 42178
A33: =A32+1 -> 42179
A34: =A33+1 -> 42180
A35: =A34+1 -> 42181
A36: =A35+1 -> 42182
A37: =A36+1 -> 42183
A38: =A37+1 -> 42184 | F38: =IFERROR(IF(INPUTS!B39="Male", 86.01*LOG(C38-D38)-70.041*LOG(INPUTS!B$7)+30.3, 163.205*LOG('BULKING TRACKER'!C38+'BULKING TRACKER'!E38-'BULKING TRACKER'!D38)-97.684*LOG(INPUTS!B$7)-104.912),0) -> 0 | G38: =IFERROR((AVERAGE(B32:B38)),0) -> 0 | H38: =IFERROR(IF(B38>0, (G31-G38)/G31,0.007), 0) -> 0.007 | I38: =IF(H38<0, "Cut 200kcal", "") | J38: =IF(AND(H38<0.005, H38>=0), "Cut 100kcal", "") | K38: =IF(AND(H38<0.006, H38>=0.005), "Cut 50kcal", "") | L38: =IF(AND(H38<0.008, H38>=0.006), "Remain Constant", "") -> Remain Constant | M38: =IF(AND(H38>=0.008,H38<0.01), "Add 50kcal", "") | N38: =IF(H38>=0.01, "Add 100kcal", "") | P38: =IF(O38>0,$O$3+O38,"")
A39: =A38+1 -> 42185
A40: =A39+1 -> 42186
A41: =A40+1 -> 42187
...

Sheet PLOTS

Sheet Water Cut Protocol
A1: Day | B1: Date | C1: Days Out | D1: Workout | E1: Water | F1: Sodium | G1: Glycogen | H1: Food Weight | I1: Supplements
A2: Monday | B2: =B3-1 -> 42177 | C2: 12 | D2: Volume | E2: 1 gal | F2: Normal | G2: Normal | H2: Normal | I2: n/a | K2: Meet day | L2: 42189
A3: Tuesday | B3: =B4-1 -> 42178 | C3: 11 | D3: GPP | E3: 1 gal | F3: Normal | G3: Normal | H3: Normal | I3: n/a | K3: Days out | L3: =L2-TODAY() -> 40
A4: Wednesday | B4: =B5-1 -> 42179 | C4: 10 | D4: Accessory | E4: 1 gal | F4: Normal | G4: Normal | H4: Normal | I4: n/a | K4: Weeks | L4: =L3/7 -> 5.7142857
A5: Thursday | B5: =B6-1 -> 42180 | C5: 9 | E5: 1 gal | F5: Normal | G5: Normal | H5: Normal | I5: n/a
A6: Friday | B6: =B7-1 -> 42181 | C6: 8 | D6: Heavy | E6: 1 gal | F6: Normal | G6: High carb day | H6: Normal | I6: n/a
A7: Saturday | B7: =B8-1 -> 42182 | C7: 7 | E7: 1 gal | F7: Normal | G7: Normal | H7: Normal | I7: n/a
A8: Sunday | B8: =B9-1 -> 42183 | C8: 6 | E8: 1 gal | F8: Normal | G8: Normal | H8: Normal | I8: n/a
A9: Monday | B9: =B10-1 -> 42184 | C9: 5 | D9: Openers | E9: 1 gal | F9: Normal | G9: High carb day | H9: Normal | I9: n/a
A10: Tuesday | B10: =B11-1 -> 42185 | C10: 4 | E10: 2 gal | F10: 5g ADDED | G10: Normal | H10: 1 Liquid Meal Before Bed | I10: Water Pill
A11: Wednesday | B11: =B12-1 -> 42186 | C11: 3 | D11: Warmups | E11: 2 gal | F11: 5g ADDED | G11: =MROUND(0.5*INPUTS!C14,1)&"g" -> 111g | H11: 1 Liquid Meal Before Bed | I11: Caffeine, Magnesium Citrate, Water Pill
A12: Thursday | B12: =B13-1 -> 42187 | C12: 2 | E12: 1 gal | F12: 1g DON’T ADD | G12: =MROUND(0.25*INPUTS!C14,1)&"g" -> 56g | H12: 2 Liquid Meal Before Bed | I12: Caffeine, Water Pill
A13: Friday | B13: =B14-1 -> 42188 | C13: 1 | E13: 0.5 gal | F13: 1g DON’T ADD | G13: Minimal | H13: All Liquid Diet
A14: Saturday | B14: =L2 -> 42189 | C14: Meet day | D14: Big Three
A16: Post weigh in
A17: Immediately drink 16oz coconut water plus 16 oz water with 2 servings Xtend/BCAAs
A18: 0.5-1g sodium each meal
A19: t ~100g of carbs every 2 hours. Keep fat to ~10g per meal initially because it will blunt the rate of digestion and thus absorption. You’re going to have to keep the fat low until towards the end of the meet. You need to maximize the rate of glycogen resynthesis.

Sheet Attempt Selection
A1: e1RM | N1: 1 | O1: 2 | P1: 3 | Q1: 4 | R1: 5 | S1: 6 | T1: 7 | U1: 8 | V1: 9 | W1: 10
A2: Exercise | B2: Weeks out | M2: 10 | N2: 1 | O2: 0.96 | P2: 0.92 | Q2: 0.89 | R2: 0.86 | S2: 0.84 | T2: 0.81 | U2: 0.79 | V2: 0.76 | W2: 0.74
B3: 10 | C3: 9 | D3: 8 | E3: 7 | F3: 6 | G3: 5 | H3: 4 | I3: 3 | J3: 2 | K3: 1 | M3: 9.5 | N3: 0.98 | O3: 0.94 | P3: 0.91 | Q3: 0.88 | R3: 0.85 | S3: 0.82 | T3: 0.8 | U3: 0.77 | V3: 0.75 | W3: 0.72
A4: Squat | B4: 500 | M4: 9 | N4: 0.96 | O4: 0.92 | P4: 0.89 | Q4: 0.86 | R4: 0.84 | S4: 0.81 | T4: 0.79 | U4: 0.76 | V4: 0.74 | W4: 0.71
A5: Bench | B5: 315 | M5: 8.5 | N5: 0.94 | O5: 0.91 | P5: 0.88 | Q5: 0.85 | R5: 0.82 | S5: 0.8 | T5: 0.77 | U5: 0.75 | V5: 0.72 | W5: 0.69
A6: Deadlift | B6: 500 | M6: 8 | N6: 0.92 | O6: 0.89 | P6: 0.86 | Q6: 0.84 | R6: 0.81 | S6: 0.79 | T6: 0.76 | U6: 0.74 | V6: 0.71 | W6: 0.68
M7: 7.5 | N7: 0.91 | O7: 0.88 | P7: 0.85 | Q7: 0.82 | R7: 0.8 | S7: 0.77 | T7: 0.75 | U7: 0.72 | V7: 0.69 | W7: 0.67
A8: e1RM | D8: New e1RM | G8: % drop | I8: Bodyweight: | M8: 7 | N8: 0.89 | O8: 0.86 | P8: 0.84 | Q8: 0.81 | R8: 0.79 | S8: 0.76 | T8: 0.74 | U8: 0.71 | V8: 0.68 | W8: 0.65
A9: Squat | B9: =MAX(B4:K4) -> 500 | D9: Squat | E9: =B9*G9 -> 490 | G9: 0.98 | I9: 83 | J9: kg | M9: 6.5 | N9: 0.88 | O9: 0.85 | P9: 0.82 | Q9: 0.8 | R9: 0.77 | S9: 0.75 | T9: 0.72 | U9: 0.69 | V9: 0.67 | W9: 0.64
A10: Bench | B10: =MAX(B5:K5) -> 315 | D10: Bench | E10: =B10*G10 -> 299.25 | G10: 0.95
A11: Deadlift | B11: =MAX(B6:K6) -> 500 | D11: Deadlift | E11: =B11*G11 -> 475 | G11: 0.95 | H11: Note: Adjust accordingly after opener test | M11: 405 | N11: 1 | O11: 2 | P11: 3 | Q11: 4 | R11: 5 | S11: 6 | T11: 7 | U11: 8 | V11: 9 | W11: 10
M12: 10 | N12: =$M$11/N2 -> 405 | O12: =$M$11/O2 -> 421.875 | P12: =$M$11/P2 -> 440.21739 | Q12: =$M$11/Q2 -> 455.05618 | R12: =$M$11/R2 -> 470.93023 | S12: =$M$11/S2 -> 482.14286 | T12: =$M$11/T2 -> 500 | U12: =$M$11/U2 -> 512.65823 | ... W12: =$M$11/W2 -> 547.2973
A13: 5 days out | M13: 9.5 | N13: =$M$11/N3 -> 413.26531 | O13: =$M$11/O3 -> 430.85106 | P13: =$M$11/P3 -> 445.05495 | Q13: =$M$11/Q3 -> 460.22727 | R13: =$M$11/R3 -> 476.47059 | S13: =$M$11/S3 -> 493.90244 | T13: =$M$11/T3 -> 506.25 | U13: =$M$11/U3 -> 525.97403 | ... W13: =$M$11/W3 -> 562.5
A14: Squat | C14: Bench | E14: Deadlift | M14: 9 | N14: =$M$11/N4 -> 421.875 | O14: =$M$11/O4 -> 440.21739 | P14: =$M$11/P4 -> 455.05618 | Q14: =$M$11/Q4 -> 470.93023 | R14: =$M$11/R4 -> 482.14286 | S14: =$M$11/S4 -> 500 | T14: =$M$11/T4 -> 512.65823 | U14: =$M$11/U4 -> 532.89474 | ... W14: =$M$11/W4 -> 570.42254
A15: Barx10 | C15: Barx10 | E15: Barx10 | M15: 8.5 | N15: =$M$11/N5 -> 430.85106 | O15: =$M$11/O5 -> 445.05495 | P15: =$M$11/P5 -> 460.22727 | Q15: =$M$11/Q5 -> 476.47059 | R15: =$M$11/R5 -> 493.90244 | S15: =$M$11/S5 -> 506.25 | T15: =$M$11/T5 -> 525.97403 | U15: =$M$11/U5 -> 540 | ... W15: =$M$11/W5 -> 586.95652
A16: =MROUND(B9*0.3,5)&"x5" -> 150x5 | C16: =MROUND(B10*0.3,5)&"x5" -> 95x5 | E16: =MROUND(B11*0.3,5)&"x5" -> 150x5 | M16: 8 | N16: =$M$11/N6 -> 440.21739 | O16: =$M$11/O6 -> 455.05618 | P16: =$M$11/P6 -> 470.93023 | Q16: =$M$11/Q6 -> 482.14286 | R16: =$M$11/R6 -> 500 | S16: =$M$11/S6 -> 512.65823 | T16: =$M$11/T6 -> 532.89474 | U16: =$M$11/U6 -> 547.2973 | ... W16: =$M$11/W6 -> 595.58824
A17: =MROUND(B9*0.5,5)&"x5" -> 250x5 | C17: =MROUND(B10*0.5,5)&"x5" -> 160x5 | E17: =MROUND(B11*0.5,5)&"x5" -> 250x5 | M17: 7.5 | N17: =$M$11/N7 -> 445.05495 | O17: =$M$11/O7 -> 460.22727 | P17: =$M$11/P7 -> 476.47059 | Q17: =$M$11/Q7 -> 493.90244 | R17: =$M$11/R7 -> 506.25 | S17: =$M$11/S7 -> 525.97403 | T17: =$M$11/T7 -> 540 | U17: =$M$11/U7 -> 562.5 | ... W17: =$M$11/W7 -> 604.47761
A18: =MROUND(B9*0.7,5)&"x3" -> 350x3 | C18: =MROUND(B10*0.7,5)&"x3" -> 220x3 | E18: =MROUND(B11*0.7,5)&"x3" -> 350x3 | M18: 7 | N18: =$M$11/N8 -> 455.05618 | O18: =$M$11/O8 -> 470.93023 | P18: =$M$11/P8 -> 482.14286 | Q18: =$M$11/Q8 -> 500 | R18: =$M$11/R8 -> 512.65823 | S18: =$M$11/S8 -> 532.89474 | T18: =$M$11/T8 -> 547.2973 | U18: =$M$11/U8 -> 570.42254 | ... W18: =$M$11/W8 -> 623.07692
A19: =MROUND(B9*0.8,5)&"x1" -> 400x1 | C19: =MROUND(B10*0.8,5)&"x1" -> 250x1 | E19: =MROUND(B11*0.8,5)&"x1" -> 400x1 | M19: 6.5 | N19: =$M$11/N9 -> 460.22727 | O19: =$M$11/O9 -> 476.47059 | P19: =$M$11/P9 -> 493.90244 | Q19: =$M$11/Q9 -> 506.25 | R19: =$M$11/R9 -> 525.97403 | S19: =$M$11/S9 -> 540 | T19: =$M$11/T9 -> 562.5 | U19: =$M$11/U9 -> 586.95652 | ... W19: =$M$11/W9 -> 632.8125
A20: =MROUND(B9*0.9,5)&"x1" -> 450x1 | B20: =MROUND(B9*0.92,5)&"x1" -> 460x1 | C20: =MROUND(B10*0.9,5)&"x1" -> 285x1 | D20: =MROUND(B10*0.92,5)&"x1" -> 290x1 | E20: =MROUND(B11*0.9,5)&"x1" -> 450x1 | F20: =MROUND(B11*0.92,5)&"x1" -> 460x1
A21: Note: If the 80%x1 feels easier than normal, go for the higher number
A23: 3 days out | H23: Warmups
A24: Squat | C24: Bench | E24: Deadlift | H24: Squat | J24: Bench | L24: Deadlift
A25: Barx10 | C25: Barx10 | E25: Barx10 | H25: Barx10 | J25: Barx10 | L25: Barx10
A26: =MROUND(E9*0.3,5)&"x5" -> 145x5 | C26: =MROUND(E10*0.3,5)&"x5" -> 90x5 | E26: =MROUND(E11*0.3,5)&"x5" -> 145x5 | H26: =MROUND((E9*83/183)*0.3,2.5)&"x5" -> 67.5x5 | J26: =MROUND((E10*83/183)*0.3,2.5)&"x5" -> 40x5 | L26: =MROUND((E11*83/183)*0.3,2.5)&"x5" -> 65x5
A27: =MROUND(E9*0.5,5)&"x5" -> 245x5 | C27: =MROUND(E10*0.5,5)&"x5" -> 150x5 | E27: =MROUND(E11*0.5,5)&"x5" -> 240x5 | H27: =MROUND((E9*83/183)*0.5,2.5)&"x5" -> 110x5 | J27: =MROUND((E10*83/183)*0.5,2.5)&"x5" -> 67.5x5 | L27: =MROUND((E11*83/183)*0.5,2.5)&"x5" -> 107.5x5
A28: =MROUND(E9*0.7,5)&"x3" -> 345x3 | C28: =MROUND(E10*0.7,5)&"x3" -> 210x3 | E28: =MROUND(E11*0.7,5)&"x3" -> 335x3 | H28: =MROUND((E9*83/183)*0.7,2.5)&"x3" -> 155x3 | J28: =MROUND((E10*83/183)*0.7,2.5)&"x3" -> 95x3 | L28: =MROUND((E11*83/183)*0.7,2.5)&"x3" -> 150x3
A29: =MROUND(E9*0.8,5)&"x1" -> 390x1 | C29: =MROUND(E10*0.8,5)&"x1" -> 240x1 | E29: =MROUND(E11*0.8,5)&"x1" -> 380x1 | H29: =MROUND((E9*83/183)*0.8,2.5)&"x1" -> 177.5x1 | J29: =MROUND((E10*83/183)*0.8,2.5)&"x1" -> 107.5x1 | L29: =MROUND((E11*83/183)*0.8,2.5)&"x1" -> 172.5x1 | V29: =31-1.75 -> 29.25
A31: Meet Warmups | H31: Meet Attempts | P31: Total | R31: Wilks
A32: Squat | C32: Bench | E32: Deadlift | I32: Squat | K32: Bench | M32: Deadlift | P32: =I33+K33+M33 -> 517.5 | Q32: =J33+L33+N33 -> 527.5 | R32: =(500/((-216.0475144)+(16.2606339*$I$9)+(-0.002388645*$I$9*$I$9)+(-0.00113732*$I$9*$I$9*$I$9)+(0.00000701863*$I$9*$I$9*$I$9*$I$9)+(-0.00000001291*$I$9*$I$9*$I$9*$I$9*$I$9)))*P32 -> 345.43095 | S32: =(500/((-216.0475144)+(16.2606339*$I$9)+(-0.002388645*$I$9*$I$9)+(-0.00113732*$I$9*$I$9*$I$9)+(0.00000701863*$I$9*$I$9*$I$9*$I$9)+(-0.00000001291*$I$9*$I$9*$I$9*$I$9*$I$9)))*Q32 -> 352.10595
A33: Barx10 | C33: Barx10 | E33: Barx10 | H33: Opener | I33: =MROUND(A45,2.5) -> 200 | J33: =MROUND(B45,2.5) -> 205 | K33: =MROUND(C45,2.5) -> 122.5 | L33: =MROUND(D45,2.5) -> 125 | M33: =MROUND(E45,2.5) -> 195 | N33: =MROUND(F45,2.5) -> 197.5 | P33: =I34+K34+M34 -> 540 | Q33: =J34+L34+N34 -> 557.5 | R33: =(500/((-216.0475144)+(16.2606339*$I$9)+(-0.002388645*$I$9*$I$9)+(-0.00113732*$I$9*$I$9*$I$9)+(0.00000701863*$I$9*$I$9*$I$9*$I$9)+(-0.00000001291*$I$9*$I$9*$I$9*$I$9*$I$9)))*P33 -> 360.44969 | S33: =(500/((-216.0475144)+(16.2606339*$I$9)+(-0.002388645*$I$9*$I$9)+(-0.00113732*$I$9*$I$9*$I$9)+(0.00000701863*$I$9*$I$9*$I$9*$I$9)+(-0.00000001291*$I$9*$I$9*$I$9*$I$9*$I$9)))*Q33 -> 372.13093
A34: =MROUND((E9*(83/183))*0.3,2.5)&"x5" -> 67.5x5 | C34: =MROUND((E10*(83/183))*0.3,2.5)&"x5" -> 40x5 | E34: =MROUND((E11*(83/183))*0.3,2.5)&"x5" -> 65x5 | H34: Second | I34: =MROUND(A46,2.5) -> 210 | J34: =MROUND(B46,2.5) -> 215 | K34: =MROUND(C46,2.5) -> 127.5 | L34: =MROUND(D46,2.5) -> 132.5 | M34: =MROUND(E46,2.5) -> 202.5 | N34: =MROUND(F46,2.5) -> 210 | P34: =I35+K35+M35 -> 560 | Q34: =J35+L35+N35 -> 585 | R34: =(500/((-216.0475144)+(16.2606339*$I$9)+(-0.002388645*$I$9*$I$9)+(-0.00113732*$I$9*$I$9*$I$9)+(0.00000701863*$I$9*$I$9*$I$9*$I$9)+(-0.00000001291*$I$9*$I$9*$I$9*$I$9*$I$9)))*P34 -> 373.79968 | S34: =(500/((-216.0475144)+(16.2606339*$I$9)+(-0.002388645*$I$9*$I$9)+(-0.00113732*$I$9*$I$9*$I$9)+(0.00000701863*$I$9*$I$9*$I$9*$I$9)+(-0.00000001291*$I$9*$I$9*$I$9*$I$9*$I$9)))*Q34 -> 390.48716
A35: =MROUND((E9*(83/183))*0.5,2.5)&"x5" -> 110x5 | C35: =MROUND((E10*(83/183))*0.5,2.5)&"x5" -> 67.5x5 | E35: =MROUND((E11*(83/183))*0.5,2.5)&"x5" -> 107.5x5 | H35: Third | I35: =MROUND(A47,2.5) -> 217.5 | J35: =MROUND(B47,2.5) -> 227.5 | K35: =MROUND(C47,2.5) -> 132.5 | L35: =MROUND(D47,2.5) -> 137.5 | M35: =MROUND(E47,2.5) -> 210 | N35: =MROUND(F47,2.5) -> 220 | P35: 562.5
A36: =MROUND((E9*(83/183))*0.7,2.5)&"x3" -> 155x3 | C36: =MROUND((E10*(83/183))*0.7,2.5)&"x3" -> 95x3 | E36: =MROUND((E11*(83/183))*0.7,2.5)&"x3" -> 150x3
A37: =MROUND((E9*(83/183))*0.8,2.5)&"x1" -> 177.5x1 | C37: =MROUND((E10*(83/183))*0.8,2.5)&"x1" -> 107.5x1 | E37: =MROUND((E11*(83/183))*0.8,2.5)&"x1" -> 172.5x1
A39: Meet Attempts (Calculation purposes)
A40: Squat | C40: Bench | E40: Deadlift
A41: =E9*0.9 -> 441 | B41: =E9*0.92 -> 450.8 | C41: =E10*0.9 -> 269.325 | D41: =E10*0.92 -> 275.31 | E41: =E11*0.9 -> 427.5 | F41: =E11*0.92 -> 437
A42: =E9*0.94 -> 460.6 | B42: =E9*0.97 -> 475.3 | C42: =E10*0.94 -> 281.295 | D42: =E10*0.97 -> 290.2725 | E42: =E11*0.94 -> 446.5 | F42: =E11*0.97 -> 460.75
A43: =E9*0.98 -> 480.2 | B43: =E9*1.02 -> 499.8 | C43: =E10*0.98 -> 293.265 | D43: =E10*1.02 -> 305.235 | E43: =E11*0.98 -> 465.5 | F43: =E11*1.02 -> 484.5
...

Sheet Sheet1
D3: 25 | F3: 20 | H3: 15 | J3: 10 | L3: 5 | N3: 2.5 | P3: 1.25 | R3: collar
B4: 215 | D4: =ROUNDDOWN(((B4-25)/25)/2,0) -> 3 | F4: =ROUNDDOWN(((B4-25-(D4*2*25))/20)/2,0) -> 1 | H4: =ROUNDDOWN(((B4-25-(D4*2*25)-(F4*2*20))/15)/2,0) -> 0 | J4: =ROUNDDOWN(((B4-25-(D4*2*25)-(F4*2*20)-(H4*2*15))/10)/2,0) -> 0 | L4: =ROUNDDOWN(((B4-25-(D4*2*25)-(F4*2*20)-(H4*2*15)-(J4*2*10))/5)/2,0) -> 0 | N4: =ROUNDDOWN(((B4-25-(D4*2*25)-(F4*2*20)-(H4*2*15)-(J4*2*10)-(L4*2*5))/2.5)/2,0) -> 0 | P4: =ROUNDDOWN(((B4-25-(D4*2*25)-(F4*2*20)-(H4*2*15)-(J4*2*10)-(L4*2*5)-(N4*2*2.5))/1.25)/2,0) -> 0 | R4: 1
X5: Squat
X6: =0.3*'Attempt Selection'!$E$9 -> 147 | Y6: =MROUND(X6*(83/183),2.5) -> 67.5
X7: =0.5*'Attempt Selection'!$E$9 -> 245 | Y7: =MROUND(X7*(83/183),2.5) -> 110
B8: Warmups | X8: =0.7*'Attempt Selection'!$E$9 -> 343 | Y8: =MROUND(X8*(83/183),2.5) -> 155
B9: Squats | D9: 25 | F9: 20 | H9: 15 | J9: 10 | L9: 5 | N9: 2.5 | P9: 1.25 | R9: collar | X9: =0.8*'Attempt Selection'!$E$9 -> 392 | Y9: =MROUND(X9*(83/183),2.5) -> 177.5
B10: =Y6 -> 67.5 | D10: =ROUNDDOWN(((B10-25)/25)/2,0) -> 0 | F10: =ROUNDDOWN(((B10-25-(D10*2*25))/20)/2,0) -> 1 | H10: =ROUNDDOWN(((B10-25-(D10*2*25)-(F10*2*20))/15)/2,0) -> 0 | J10: =ROUNDDOWN(((B10-25-(D10*2*25)-(F10*2*20)-(H10*2*15))/10)/2,0) -> 0 | L10: =ROUNDDOWN(((B10-25-(D10*2*25)-(F10*2*20)-(H10*2*15)-(J10*2*10))/5)/2,0) -> 0 | N10: =ROUNDDOWN(((B10-25-(D10*2*25)-(F10*2*20)-(H10*2*15)-(J10*2*10)-(L10*2*5))/2.5)/2,0) -> 0 | P10: =ROUNDDOWN(((B10-25-(D10*2*25)-(F10*2*20)-(H10*2*15)-(J10*2*10)-(L10*2*5)-(N10*2*2.5))/1.25)/2,0) -> 1 | R10: 1 | X10: Bench
B11: =Y7 -> 110 | D11: =ROUNDDOWN(((B11-25)/25)/2,0) -> 1 | F11: =ROUNDDOWN(((B11-25-(D11*2*25))/20)/2,0) -> 0 | H11: =ROUNDDOWN(((B11-25-(D11*2*25)-(F11*2*20))/15)/2,0) -> 1 | J11: =ROUNDDOWN(((B11-25-(D11*2*25)-(F11*2*20)-(H11*2*15))/10)/2,0) -> 0 | L11: =ROUNDDOWN(((B11-25-(D11*2*25)-(F11*2*20)-(H11*2*15)-(J11*2*10))/5)/2,0) -> 0 | N11: =ROUNDDOWN(((B11-25-(D11*2*25)-(F11*2*20)-(H11*2*15)-(J11*2*10)-(L11*2*5))/2.5)/2,0) -> 1 | P11: =ROUNDDOWN(((B11-25-(D11*2*25)-(F11*2*20)-(H11*2*15)-(J11*2*10)-(L11*2*5)-(N11*2*2.5))/1.25)/2,0) -> 0 | R11: 1 | X11: =0.3*'Attempt Selection'!$E$10 -> 89.775 | Y11: =MROUND(X11*(83/183),2.5) -> 40
B12: =Y8 -> 155 | D12: =ROUNDDOWN(((B12-25)/25)/2,0) -> 2 | F12: =ROUNDDOWN(((B12-25-(D12*2*25))/20)/2,0) -> 0 | H12: =ROUNDDOWN(((B12-25-(D12*2*25)-(F12*2*20))/15)/2,0) -> 1 | J12: =ROUNDDOWN(((B12-25-(D12*2*25)-(F12*2*20)-(H12*2*15))/10)/2,0) -> 0 | L12: =ROUNDDOWN(((B12-25-(D12*2*25)-(F12*2*20)-(H12*2*15)-(J12*2*10))/5)/2,0) -> 0 | N12: =ROUNDDOWN(((B12-25-(D12*2*25)-(F12*2*20)-(H12*2*15)-(J12*2*10)-(L12*2*5))/2.5)/2,0) -> 0 | P12: =ROUNDDOWN(((B12-25-(D12*2*25)-(F12*2*20)-(H12*2*15)-(J12*2*10)-(L12*2*5)-(N12*2*2.5))/1.25)/2,0) -> 0 | R12: 1 | X12: =0.5*'Attempt Selection'!$E$10 -> 149.625 | Y12: =MROUND(X12*(83/183),2.5) -> 67.5
B13: =Y9 -> 177.5 | D13: =ROUNDDOWN(((B13-25)/25)/2,0) -> 3 | F13: =ROUNDDOWN(((B13-25-(D13*2*25))/20)/2,0) -> 0 | H13: =ROUNDDOWN(((B13-25-(D13*2*25)-(F13*2*20))/15)/2,0) -> 0 | J13: =ROUNDDOWN(((B13-25-(D13*2*25)-(F13*2*20)-(H13*2*15))/10)/2,0) -> 0 | L13: =ROUNDDOWN(((B13-25-(D13*2*25)-(F13*2*20)-(H13*2*15)-(J13*2*10))/5)/2,0) -> 0 | N13: =ROUNDDOWN(((B13-25-(D13*2*25)-(F13*2*20)-(H13*2*15)-(J13*2*10)-(L13*2*5))/2.5)/2,0) -> 0 | P13: =ROUNDDOWN(((B13-25-(D13*2*25)-(F13*2*20)-(H13*2*15)-(J13*2*10)-(L13*2*5)-(N13*2*2.5))/1.25)/2,0) -> 1 | R13: 1 | X13: =0.7*'Attempt Selection'!$E$10 -> 209.475 | Y13: =MROUND(X13*(83/183),2.5) -> 95
B14: Bench | D14: 25 | F14: 20 | H14: 15 | J14: 10 | L14: 5 | N14: 2.5 | P14: 1.25 | R14: collar | X14: =0.8*'Attempt Selection'!$E$10 -> 239.4 | Y14: =MROUND(X14*(83/183),2.5) -> 107.5
B15: =Y11 -> 40 | D15: =ROUNDDOWN(((B15-25)/25)/2,0) -> 0 | F15: =ROUNDDOWN(((B15-25-(D15*2*25))/20)/2,0) -> 0 | H15: =ROUNDDOWN(((B15-25-(D15*2*25)-(F15*2*20))/15)/2,0) -> 0 | J15: =ROUNDDOWN(((B15-25-(D15*2*25)-(F15*2*20)-(H15*2*15))/10)/2,0) -> 0 | L15: =ROUNDDOWN(((B15-25-(D15*2*25)-(F15*2*20)-(H15*2*15)-(J15*2*10))/5)/2,0) -> 1 | N15: =ROUNDDOWN(((B15-25-(D15*2*25)-(F15*2*20)-(H15*2*15)-(J15*2*10)-(L15*2*5))/2.5)/2,0) -> 1 | P15: =ROUNDDOWN(((B15-25-(D15*2*25)-(F15*2*20)-(H15*2*15)-(J15*2*10)-(L15*2*5)-(N15*2*2.5))/1.25)/2,0) -> 0 | R15: 1 | X15: Deadlift
B16: =Y12 -> 67.5 | D16: =ROUNDDOWN(((B16-25)/25)/2,0) -> 0 | F16: =ROUNDDOWN(((B16-25-(D16*2*25))/20)/2,0) -> 1 | H16: =ROUNDDOWN(((B16-25-(D16*2*25)-(F16*2*20))/15)/2,0) -> 0 | J16: =ROUNDDOWN(((B16-25-(D16*2*25)-(F16*2*20)-(H16*2*15))/10)/2,0) -> 0 | L16: =ROUNDDOWN(((B16-25-(D16*2*25)-(F16*2*20)-(H16*2*15)-(J16*2*10))/5)/2,0) -> 0 | N16: =ROUNDDOWN(((B16-25-(D16*2*25)-(F16*2*20)-(H16*2*15)-(J16*2*10)-(L16*2*5))/2.5)/2,0) -> 0 | P16: =ROUNDDOWN(((B16-25-(D16*2*25)-(F16*2*20)-(H16*2*15)-(J16*2*10)-(L16*2*5)-(N16*2*2.5))/1.25)/2,0) -> 1 | R16: 1 | X16: =0.3*'Attempt Selection'!$E$11 -> 142.5 | Y16: =MROUND(X16*(83/183),2.5) -> 65
B17: =Y13 -> 95 | D17: =ROUNDDOWN(((B17-25)/25)/2,0) -> 1 | F17: =ROUNDDOWN(((B17-25-(D17*2*25))/20)/2,0) -> 0 | H17: =ROUNDDOWN(((B17-25-(D17*2*25)-(F17*2*20))/15)/2,0) -> 0 | J17: =ROUNDDOWN(((B17-25-(D17*2*25)-(F17*2*20)-(H17*2*15))/10)/2,0) -> 1 | L17: =ROUNDDOWN(((B17-25-(D17*2*25)-(F17*2*20)-(H17*2*15)-(J17*2*10))/5)/2,0) -> 0 | N17: =ROUNDDOWN(((B17-25-(D17*2*25)-(F17*2*20)-(H17*2*15)-(J17*2*10)-(L17*2*5))/2.5)/2,0) -> 0 | P17: =ROUNDDOWN(((B17-25-(D17*2*25)-(F17*2*20)-(H17*2*15)-(J17*2*10)-(L17*2*5)-(N17*2*2.5))/1.25)/2,0) -> 0 | R17: 1 | X17: =0.5*'Attempt Selection'!$E$11 -> 237.5 | Y17: =MROUND(X17*(83/183),2.5) -> 107.5
B18: =Y14 -> 107.5 | D18: =ROUNDDOWN(((B18-25)/25)/2,0) -> 1 | F18: =ROUNDDOWN(((B18-25-(D18*2*25))/20)/2,0) -> 0 | H18: =ROUNDDOWN(((B18-25-(D18*2*25)-(F18*2*20))/15)/2,0) -> 1 | J18: =ROUNDDOWN(((B18-25-(D18*2*25)-(F18*2*20)-(H18*2*15))/10)/2,0) -> 0 | L18: =ROUNDDOWN(((B18-25-(D18*2*25)-(F18*2*20)-(H18*2*15)-(J18*2*10))/5)/2,0) -> 0 | N18: =ROUNDDOWN(((B18-25-(D18*2*25)-(F18*2*20)-(H18*2*15)-(J18*2*10)-(L18*2*5))/2.5)/2,0) -> 0 | P18: =ROUNDDOWN(((B18-25-(D18*2*25)-(F18*2*20)-(H18*2*15)-(J18*2*10)-(L18*2*5)-(N18*2*2.5))/1.25)/2,0) -> 1 | R18: 1 | X18: =0.7*'Attempt Selection'!$E$11 -> 332.5 | Y18: =MROUND(X18*(83/183),2.5) -> 150
B19: Deadlift | D19: 25 | F19: 20 | H19: 15 | J19: 10 | L19: 5 | N19: 2.5 | P19: 1.25 | R19: collar | X19: =0.8*'Attempt Selection'!$E$11 -> 380 | Y19: =MROUND(X19*(83/183),2.5) -> 172.5
B20: =Y16 -> 65 | D20: =ROUNDDOWN(((B20-25)/25)/2,0) -> 0 | F20: =ROUNDDOWN(((B20-25-(D20*2*25))/20)/2,0) -> 1 | H20: =ROUNDDOWN(((B20-25-(D20*2*25)-(F20*2*20))/15)/2,0) -> 0 | J20: =ROUNDDOWN(((B20-25-(D20*2*25)-(F20*2*20)-(H20*2*15))/10)/2,0) -> 0 | L20: =ROUNDDOWN(((B20-25-(D20*2*25)-(F20*2*20)-(H20*2*15)-(J20*2*10))/5)/2,0) -> 0 | N20: =ROUNDDOWN(((B20-25-(D20*2*25)-(F20*2*20)-(H20*2*15)-(J20*2*10)-(L20*2*5))/2.5)/2,0) -> 0 | P20: =ROUNDDOWN(((B20-25-(D20*2*25)-(F20*2*20)-(H20*2*15)-(J20*2*10)-(L20*2*5)-(N20*2*2.5))/1.25)/2,0) -> 0 | R20: 1
B21: =Y17 -> 107.5 | D21: =ROUNDDOWN(((B21-25)/25)/2,0) -> 1 | F21: =ROUNDDOWN(((B21-25-(D21*2*25))/20)/2,0) -> 0 | H21: =ROUNDDOWN(((B21-25-(D21*2*25)-(F21*2*20))/15)/2,0) -> 1 | J21: =ROUNDDOWN(((B21-25-(D21*2*25)-(F21*2*20)-(H21*2*15))/10)/2,0) -> 0 | L21: =ROUNDDOWN(((B21-25-(D21*2*25)-(F21*2*20)-(H21*2*15)-(J21*2*10))/5)/2,0) -> 0 | N21: =ROUNDDOWN(((B21-25-(D21*2*25)-(F21*2*20)-(H21*2*15)-(J21*2*10)-(L21*2*5))/2.5)/2,0) -> 0 | P21: =ROUNDDOWN(((B21-25-(D21*2*25)-(F21*2*20)-(H21*2*15)-(J21*2*10)-(L21*2*5)-(N21*2*2.5))/1.25)/2,0) -> 1 | R21: 1
B22: =Y18 -> 150 | D22: =ROUNDDOWN(((B22-25)/25)/2,0) -> 2 | F22: =ROUNDDOWN(((B22-25-(D22*2*25))/20)/2,0) -> 0 | H22: =ROUNDDOWN(((B22-25-(D22*2*25)-(F22*2*20))/15)/2,0) -> 0 | J22: =ROUNDDOWN(((B22-25-(D22*2*25)-(F22*2*20)-(H22*2*15))/10)/2,0) -> 1 | L22: =ROUNDDOWN(((B22-25-(D22*2*25)-(F22*2*20)-(H22*2*15)-(J22*2*10))/5)/2,0) -> 0 | N22: =ROUNDDOWN(((B22-25-(D22*2*25)-(F22*2*20)-(H22*2*15)-(J22*2*10)-(L22*2*5))/2.5)/2,0) -> 1 | P22: =ROUNDDOWN(((B22-25-(D22*2*25)-(F22*2*20)-(H22*2*15)-(J22*2*10)-(L22*2*5)-(N22*2*2.5))/1.25)/2,0) -> 0 | R22: 1
B23: =Y19 -> 172.5 | D23: =ROUNDDOWN(((B23-25)/25)/2,0) -> 2 | F23: =ROUNDDOWN(((B23-25-(D23*2*25))/20)/2,0) -> 1 | H23: =ROUNDDOWN(((B23-25-(D23*2*25)-(F23*2*20))/15)/2,0) -> 0 | J23: =ROUNDDOWN(((B23-25-(D23*2*25)-(F23*2*20)-(H23*2*15))/10)/2,0) -> 0 | L23: =ROUNDDOWN(((B23-25-(D23*2*25)-(F23*2*20)-(H23*2*15)-(J23*2*10))/5)/2,0) -> 0 | N23: =ROUNDDOWN(((B23-25-(D23*2*25)-(F23*2*20)-(H23*2*15)-(J23*2*10)-(L23*2*5))/2.5)/2,0) -> 1 | P23: =ROUNDDOWN(((B23-25-(D23*2*25)-(F23*2*20)-(H23*2*15)-(J23*2*10)-(L23*2*5)-(N23*2*2.5))/1.25)/2,0) -> 1 | R23: 1
